<?xml version="1.0" encoding="UTF-8"?>
<!-- Generated by org.testng.reporters.JUnitReportReporter -->
<testsuite skipped="1" hostname="KILLZONE-PC" name="com.testngexamples.intellipaatsolutions.MultipleTests" tests="4" failures="2" timestamp="23 Sep 2018 17:02:59 GMT" time="0.012" errors="0">
  <testcase name="launch" time="0.004" classname="com.testngexamples.intellipaatsolutions.MultipleTests"/>
  <testcase name="compose" time="0.004" classname="com.testngexamples.intellipaatsolutions.MultipleTests">
    <failure type="java.lang.AssertionError" message="expected [a] but found [A]">
      <![CDATA[java.lang.AssertionError: expected [a] but found [A]
at org.testng.Assert.fail(Assert.java:96)
at org.testng.Assert.failNotEquals(Assert.java:776)
at org.testng.Assert.assertEqualsImpl(Assert.java:137)
at org.testng.Assert.assertEquals(Assert.java:118)
at org.testng.Assert.assertEquals(Assert.java:610)
at org.testng.Assert.assertEquals(Assert.java:620)
at com.testngexamples.intellipaatsolutions.MultipleTests.compose(MultipleTests.java:56)
at sun.reflect.NativeMethodAccessorImpl.invoke0(Native Method)
at sun.reflect.NativeMethodAccessorImpl.invoke(Unknown Source)
at sun.reflect.DelegatingMethodAccessorImpl.invoke(Unknown Source)
at java.lang.reflect.Method.invoke(Unknown Source)
at org.testng.internal.MethodInvocationHelper.invokeMethod(MethodInvocationHelper.java:124)
at org.testng.internal.Invoker.invokeMethod(Invoker.java:580)
at org.testng.internal.Invoker.invokeTestMethod(Invoker.java:716)
at org.testng.internal.Invoker.invokeTestMethods(Invoker.java:988)
at org.testng.internal.TestMethodWorker.invokeTestMethods(TestMethodWorker.java:125)
at org.testng.internal.TestMethodWorker.run(TestMethodWorker.java:109)
at java.util.concurrent.ThreadPoolExecutor.runWorker(Unknown Source)
at java.util.concurrent.ThreadPoolExecutor$Worker.run(Unknown Source)
at java.lang.Thread.run(Unknown Source)
]]>
    </failure>
  </testcase> <!-- compose -->
  <testcase name="login" time="0.004" classname="com.testngexamples.intellipaatsolutions.MultipleTests">
    <failure type="java.lang.AssertionError" message="expected [a] but found [A]">
      <![CDATA[java.lang.AssertionError: expected [a] but found [A]
at org.testng.Assert.fail(Assert.java:96)
at org.testng.Assert.failNotEquals(Assert.java:776)
at org.testng.Assert.assertEqualsImpl(Assert.java:137)
at org.testng.Assert.assertEquals(Assert.java:118)
at org.testng.Assert.assertEquals(Assert.java:610)
at org.testng.Assert.assertEquals(Assert.java:620)
at com.testngexamples.intellipaatsolutions.MultipleTests.login(MultipleTests.java:50)
at sun.reflect.NativeMethodAccessorImpl.invoke0(Native Method)
at sun.reflect.NativeMethodAccessorImpl.invoke(Unknown Source)
at sun.reflect.DelegatingMethodAccessorImpl.invoke(Unknown Source)
at java.lang.reflect.Method.invoke(Unknown Source)
at org.testng.internal.MethodInvocationHelper.invokeMethod(MethodInvocationHelper.java:124)
at org.testng.internal.Invoker.invokeMethod(Invoker.java:580)
at org.testng.internal.Invoker.invokeTestMethod(Invoker.java:716)
at org.testng.internal.Invoker.invokeTestMethods(Invoker.java:988)
at org.testng.internal.TestMethodWorker.invokeTestMethods(TestMethodWorker.java:125)
at org.testng.internal.TestMethodWorker.run(TestMethodWorker.java:109)
at java.util.concurrent.ThreadPoolExecutor.runWorker(Unknown Source)
at java.util.concurrent.ThreadPoolExecutor$Worker.run(Unknown Source)
at java.lang.Thread.run(Unknown Source)
]]>
    </failure>
  </testcase> <!-- login -->
  <testcase name="logout" time="0.000" classname="com.testngexamples.intellipaatsolutions.MultipleTests">
    <skipped/>
  </testcase> <!-- logout -->
</testsuite> <!-- com.testngexamples.intellipaatsolutions.MultipleTests -->
